Workbook
Name a: #REF!
Name a: #REF!
Name a: #REF!
Name adfads: #REF!
Name adfads: #REF!
Name adfads: #REF!
Name DATA1: #REF!
Name DATA1: #REF!
Name DATA1: #REF!
Name DATA10: #REF!
Name DATA10: #REF!
Name DATA10: #REF!
Name DATA11: #REF!
Name DATA11: #REF!
Name DATA11: #REF!
Name DATA12: #REF!
Name DATA12: #REF!
Name DATA12: #REF!
Name DATA13: #REF!
Name DATA13: #REF!
Name DATA13: #REF!
Name DATA14: #REF!
Name DATA14: #REF!
Name DATA14: #REF!
Name DATA15: #REF!
Name DATA15: #REF!
Name DATA15: #REF!
Name DATA16: #REF!
Name DATA16: #REF!
Name DATA16: #REF!
Name DATA17: #REF!
Name DATA17: #REF!
Name DATA17: #REF!
Name DATA18: #REF!
Name DATA18: #REF!
Name DATA18: #REF!
Name DATA19: #REF!
Name DATA19: #REF!
Name DATA19: #REF!
Name DATA2: #REF!
Name DATA2: #REF!
Name DATA2: #REF!
Name DATA21: #REF!
Name DATA21: #REF!
Name DATA21: #REF!
Name DATA22: #REF!
Name DATA22: #REF!
Name DATA22: #REF!
Name DATA3: #REF!
Name DATA3: #REF!
Name DATA3: #REF!
Name DATA4: #REF!
Name DATA4: #REF!
Name DATA4: #REF!
Name DATA5: #REF!
Name DATA5: #REF!
Name DATA5: #REF!
Name DATA6: #REF!
Name DATA6: #REF!
Name DATA6: #REF!

Sheet COVER
A3: Company Name: | D3: PT. Indomobil Global Transportasi Cab Pasar Minggu
B6: SPARE PARTS MONTHLY REPORT
B7: 46054
B13: DLR OPERATION INFORMATION
A16: PERFORMANCE RESULT | F16: TARGET | H16: ACTUAL | J16: DIFFERENCE | K16: % Ach.
A17: Retail Sales By Customer | E17: End User | J17: =H17-F17 -> 0 | K17: =H17/F17 -> #DIV/0!
E18: Workshop | J18: =H18-F18 -> 0 | K18: =H18/F18 -> #DIV/0!
E19: Partshop | J19: =H19-F19 -> 0 | K19: =H19/F19 -> #DIV/0!
E20: TOTAL | F20: =SUM(F17:G19) -> 0 | H20: =SUM(H17:I19) -> 0 | J20: =H20-F20 -> 0 | K20: =H20/F20 -> #DIV/0!
A21: Retail Sales By Category | E21: Cat.2 | J21: =H21-F21 -> 0 | K21: =H21/F21 -> #DIV/0!
E22: Cat.3 | J22: =H22-F22 -> 0 | K22: =H22/F22 -> #DIV/0!
E23: Cat.5 | J23: =H23-F23 -> 0 | K23: =H23/F23 -> #DIV/0!
E24: Oil & Acc | J24: =H24-F24 -> 0 | K24: =H24/F24 -> #DIV/0!
A31: DLR OUTLETS
A32: No. | B32: H/O or BRANCH | D32: OUTLET NAME | H32: No. of Fleet Sales | J32: No. of Partshop Sales | K32: Keterangan
A33: 1 | B33: H/O | D33: HEAD OFFICE A
A34: 2 | B34: BRANCH | D34: BRANCH A
A35: 3 | B35: BRANCH | D35: BRANCH B
A36: 4 | B36: BRANCH | D36: BRANCH C
A37: 5 | B37: BRANCH
A38: 6 | B38: BRANCH
A39: 7 | B39: BRANCH
A40: 8 | B40: BRANCH
A41: 9 | B41: BRANCH
A42: 10 | B42: BRANCH

Sheet DETAIL SALES
A2: LAPORAN HARIAN PENJUALAN SPARE PARTS | J2: RETAIL SALES | K2: Pick UP | L2: CDE | M2: CDD | N2: OIL & ACC | O2: TOTAL | P2: % | R2: Fill Rate All Item By Category | S2: Pick UP | T2: CDE | U2: CDD | V2: OIL & ACC | W2: TOTAL | Y2: Fill Rate All Item By Customer | AA2: END USER | AB2: WORKSHOP | AC2: PARTSHOP | AD2: TOTAL
A3: NAMA DEALER | E3: : | J3: End User | K3: =SUMIFS($Y$10:$Y$7501,$N$10:$N$7501,"End User",$P$10:$P$7501,"CAT.2") -> 0 | L3: =SUMIFS($Y$10:$Y$7501,$N$10:$N$7501,"End User",$P$10:$P$7501,"CAT.3") -> 0 | M3: =SUMIFS($Y$10:$Y$7501,$N$10:$N$7501,"End User",$P$10:$P$7501,"CAT.5") -> 0 | N3: =SUMIFS($Y$10:$Y$7501,$N$10:$N$7501,"End User",$P$10:$P$7501,"OIL & ACC") -> 0 | O3: =SUM(K3:N3) -> 0 | P3: =O3/O6 -> #DIV/0!
A4: PERIODE | E4: : | F4: 46054 | J4: Workshop | K4: =SUMIFS($Y$10:$Y$7501,$N$10:$N$7501,"Workshop",$P$10:$P$7501,"CAT.2") -> 0 | L4: =SUMIFS($Y$10:$Y$7501,$N$10:$N$7501,"Workshop",$P$10:$P$7501,"CAT.3") -> 0 | M4: =SUMIFS($Y$10:$Y$7501,$N$10:$N$7501,"Workshop",$P$10:$P$7501,"CAT.5") -> 0 | N4: =SUMIFS($Y$10:$Y$7501,$N$10:$N$7501,"Workshop",$P$10:$P$7501,"OIL & ACC") -> 0 | O4: =SUM(K4:N4) -> 0 | P4: =O4/O6 -> #DIV/0! | R4: Line Order | S4: =COUNTIF($P$10:$P$7501,S2) -> 0 | T4: =COUNTIF($P$10:$P$7501,T2) -> 0 | U4: =COUNTIF($P$10:$P$7501,U2) -> 0 | V4: =COUNTIF($P$10:$P$7501,V2) -> 0 | W4: =SUM(S4:V4) -> 0 | Y4: No. of Item Order | AA4: =COUNTIF($N$10:$N$7501,"End User") -> 0 | AB4: =COUNTIF($N$10:$N$7501,"Workshop") -> 0 | AC4: =COUNTIF($N$10:$N$7501,"Partshop") -> 0 | AD4: =AA4+AB4+AC4 -> 0
A5: JUMLAH HARI KERJA | E5: : | J5: Partshop | K5: =SUMIFS($Y$10:$Y$7501,$N$10:$N$7501,"Partshop",$P$10:$P$7501,"CAT.2") -> 0 | L5: =SUMIFS($Y$10:$Y$7501,$N$10:$N$7501,"Partshop",$P$10:$P$7501,"CAT.3") -> 0 | M5: =SUMIFS($Y$10:$Y$7501,$N$10:$N$7501,"Partshop",$P$10:$P$7501,"CAT.5") -> 0 | N5: =SUMIFS($Y$10:$Y$7501,$N$10:$N$7501,"Partshop",$P$10:$P$7501,"OIL & ACC") -> 0 | O5: =SUM(K5:N5) -> 0 | P5: =O5/O6 -> #DIV/0! | R5: Full Supply | S5: =COUNTIFS($P$10:$P$7501,$S$2,$AB$10:$AB$7501,"Full") -> 0 | T5: =COUNTIFS($P$10:$P$7501,T2,$AB$10:$AB$7501,"Full") -> 0 | U5: =COUNTIFS($P$10:$P$7501,U2,$AB$10:$AB$7501,"Full") -> 0 | V5: =COUNTIFS($P$10:$P$7501,V2,$AB$10:$AB$7501,"Full") -> 0 | W5: =SUM(S5:V5) -> 0 | Y5: Full Supply | AA5: =COUNTIFS($N$10:$N$7501,"End User",$AB$10:$AB$7501,"Full") -> 0 | AB5: =COUNTIFS($N$10:$N$7501,"Workshop",$AB$10:$AB$7501,"Full") -> 0 | AC5: =COUNTIFS($N$10:$N$7501,"Partshop",$AB$10:$AB$7501,"Full") -> 0 | AD5: =AA5+AB5+AC5 -> 0
J6: Total | K6: =SUM(K3:K5) -> 0 | L6: =SUM(L3:L5) -> 0 | M6: =SUM(M3:M5) -> 0 | N6: =SUM(N3:N5) -> 0 | O6: =SUM(O3:O5) -> 0 | P6: =SUM(P3:P5) -> #DIV/0! | R6: Supply Rate | S6: =S5/S4 -> #DIV/0! | T6: =T5/T4 -> #DIV/0! | U6: =U5/U4 -> #DIV/0! | V6: =V5/V4 -> #DIV/0! | W6: =W5/W4 -> #DIV/0! | Y6: Supply Rate | AA6: =AA5/AA4 -> #DIV/0! | AB6: =AB5/AB4 -> #DIV/0! | AC6: =AC5/AC4 -> #DIV/0! | AD6: =AD5/AD4 -> #DIV/0!
J7: % | K7: =K6/$O$6 -> #DIV/0! | L7: =L6/$O$6 -> #DIV/0! | M7: =M6/$O$6 -> #DIV/0! | N7: =N6/$O$6 -> #DIV/0! | O7: =O6/$O$6 -> #DIV/0!
A9: No. | B9: (1) Tanggal | C9: Date | D9: Month | E9: Year | F9: (2) Nama Customer | G9: (3) Segmen Bisnis | H9: (4) Lokasi Customer (Kab/Kota) | I9: (5) Lokasi Customer (Provinsi) | J9: (6) Nomor Sales Order | K9: (7) Nomor Invoice | L9: (8) Penjualan HO/Branch | M9: (9) Status Customer New : Baru, Continue : Lama | N9: (10) Customer Type (end User, Workshop, Partshop) | O9: (11) Nama Sales | P9: (12) Category Spare Parts (Cat.2, Cat.3, Cat.5, Oil & Acc) | Q9: (13) No. Parts | R9: (14) Nama Parts | S9: (15) Qty Order | T9: (16) Qty Allocate | U9: (17) Qty Supply | V9: (18) Qty BO | W9: (19) Harga Satuan | X9: (20) @ Harga Setelah Discount | Y9: (21) Total Harga Sebelum PPN | Z9: (22) Total Harga Setelah PPN | AA9: (23) Program/Non Program | AB9: (24) Fill Rate | AC9: (25) Lost Sales | AD9: (26) Qty Lost | AE9: (27) Alasan Lost Sales | AF9: (28) Keterangan | AQ9: 2018 | BD9: Group | BE9: No. | BF9: Parts Name | BG9: Model | BH9: Parts Number | BI9: Category | BJ9: Interval Change (KM) | BK9: Qty /Unit | BL9: Mandatory Stock | BM9: SUPPLY DATE
A10: 1 | C10: =DAY(B10) -> 0 | D10: =MONTH(B10) -> 1 | E10: =YEAR(B10) -> 1900 | Y10: =X10*U10 -> 0 | Z10: =Y10*1.1 -> 0 | AB10: =IF(S10="","",IF(S10-U10=0,"Full","No")) | AC10: =IF(AND(S10>U10,V10=0),"Lost",IF(AND(S10>U10,V10<(S10-U10)),"Lost","")) | AD10: =IF(AND(S10>U10,V10=0),S10-U10,IF(AND(S10>U10,V10<(S10-U10)),S10-(U10+V10),"")) | AQ10: RETAIL SALES | BM10: 1 | BO10: 2 | BQ10: 3 | BS10: 4 | BU10: 5 | BW10: 6 | BY10: 7 | CA10: 8 | CC10: 9 | CE10: 10 | CG10: 11 | CI10: 12 | CK10: 13 | CM10: 14 | CO10: 15 | CQ10: 16 | CS10: 17 | CU10: 18 | CW10: 19 | CY10: 20 | DA10: 21 | DC10: 22 | DE10: 23 | DG10: 24 | DI10: 25 | DK10: 26 | DM10: 27 | DO10: 28 | DQ10: 29 | DS10: 30 | DU10: 31 | DW10: TOTAL
A11: 2 | C11: =DAY(B11) -> 0 | D11: =MONTH(B11) -> 1 | E11: =YEAR(B11) -> 1900 | Y11: =X11*U11 -> 0 | Z11: =Y11*1.1 -> 0 | AB11: =IF(S11="","",IF(S11-U11=0,"Full","No")) | AC11: =IF(AND(S11>U11,V11=0),"Lost",IF(AND(S11>U11,V11<(S11-U11)),"Lost","")) | AD11: =IF(AND(S11>U11,V11=0),S11-U11,IF(AND(S11>U11,V11<(S11-U11)),S11-(U11+V11),"")) | AJ11: No. | AK11: Segmen Bisnis | AL11: Keterangan | AN11: Nama Dealer | AR11: CAT.2 | AS11: CAT.3 | AT11: CAT.5 | AU11: OIL & ACC | AV11: TOTAL | AW11: % | BM11: Full | BN11: No | BO11: Full | BP11: No | BQ11: Full | BR11: No | BS11: Full | BT11: No | BU11: Full | BV11: No | BW11: Full | BX11: No | BY11: Full | BZ11: No | CA11: Full | CB11: No | CC11: Full | CD11: No | CE11: Full | CF11: No | CG11: Full | CH11: No | CI11: Full | CJ11: No | CK11: Full | CL11: No | CM11: Full | CN11: No | CO11: Full | CP11: No | CQ11: Full | CR11: No | CS11: Full | CT11: No | CU11: Full | CV11: No | CW11: Full | CX11: No | CY11: Full | CZ11: No | DA11: Full | DB11: No | DC11: Full | DD11: No | DE11: Full | DF11: No | DG11: Full | DH11: No | DI11: Full | DJ11: No | DK11: Full | DL11: No | DM11: Full | DN11: No | DO11: Full | DP11: No | DQ11: Full | DR11: No | DS11: Full | DT11: No | DU11: Full | DV11: No | DW11: Full | DX11: No | DY11: Total | DZ11: % Fill Rate
A12: 3 | C12: =DAY(B12) -> 0 | D12: =MONTH(B12) -> 1 | E12: =YEAR(B12) -> 1900 | Y12: =X12*U12 -> 0 | Z12: =Y12*1.1 -> 0 | AB12: =IF(S12="","",IF(S12-U12=0,"Full","No")) | AC12: =IF(AND(S12>U12,V12=0),"Lost",IF(AND(S12>U12,V12<(S12-U12)),"Lost","")) | AD12: =IF(AND(S12>U12,V12=0),S12-U12,IF(AND(S12>U12,V12<(S12-U12)),S12-(U12+V12),"")) | AJ12: 1 | AK12: Food Industry | AL12: Indofood, Wingsfood | AN12: PT. ANTASENA AGUNG JAYA | AQ12: End User | AR12: =SUMIFS($Y$10:$Y$7501,$N$10:$N$7501,"End User",$P$10:$P$7501,"CAT.2") -> 0 | AS12: =SUMIFS($Y$10:$Y$7501,$N$10:$N$7501,"End User",$P$10:$P$7501,"CAT.3") -> 0 | AT12: =SUMIFS($Y$10:$Y$7501,$N$10:$N$7501,"End User",$P$10:$P$7501,"CAT.5") -> 0 | AU12: =SUMIFS($Y$10:$Y$7501,$N$10:$N$7501,"End User",$P$10:$P$7501,"OIL & ACC") -> 0 | AV12: =SUM(AR12:AU12) -> 0 | AW12: =AV12/AV15 -> #DIV/0! | BD12: F S P (39) | BE12: 1 | BF12: GREASE CHASISS (16 KG) | BG12: ALL MODEL | BH12: S041041024 | BI12: =VLOOKUP(BH12,#REF!,8,FALSE) -> #REF! | BJ12: 10000 | BK12: 3 | BL12: 0 | BM12: =COUNTIFS('DETAIL SALES'!$Q$10:$Q$7501,'FILL RATE MANDATORY STOCK'!BK12,'DETAIL SALES'!$AB$10:$AB$7501,"Full",'DETAIL SALES'!$C$10:$C$7501,"1") -> 0 | BN12: =COUNTIFS('DETAIL SALES'!$Q$10:$Q$7501,'FILL RATE MANDATORY STOCK'!BK12,'DETAIL SALES'!$AB$10:$AB$7501,"No",'DETAIL SALES'!$C$10:$C$7501,"1") -> 0 | BO12: =COUNTIFS('DETAIL SALES'!$Q$10:$Q$7501,'FILL RATE MANDATORY STOCK'!BK12,'DETAIL SALES'!$AB$10:$AB$7501,"Full",'DETAIL SALES'!$C$10:$C$7501,"2") -> 0 | BP12: =COUNTIFS('DETAIL SALES'!$Q$10:$Q$7501,'FILL RATE MANDATORY STOCK'!BK12,'DETAIL SALES'!$AB$10:$AB$7501,"No",'DETAIL SALES'!$C$10:$C$7501,"2") -> 0 | BQ12: =COUNTIFS('DETAIL SALES'!$Q$10:$Q$7501,'FILL RATE MANDATORY STOCK'!BK12,'DETAIL SALES'!$AB$10:$AB$7501,"Full",'DETAIL SALES'!$C$10:$C$7501,"3") -> 0 | BR12: =COUNTIFS('DETAIL SALES'!$Q$10:$Q$7501,'FILL RATE MANDATORY STOCK'!BK12,'DETAIL SALES'!$AB$10:$AB$7501,"No",'DETAIL SALES'!$C$10:$C$7501,"3") -> 0 | BS12: =COUNTIFS('DETAIL SALES'!$Q$10:$Q$7501,'FILL RATE MANDATORY STOCK'!BK12,'DETAIL SALES'!$AB$10:$AB$7501,"Full",'DETAIL SALES'!$C$10:$C$7501,"4") -> 0 | BT12: =COUNTIFS('DETAIL SALES'!$Q$10:$Q$7501,'FILL RATE MANDATORY STOCK'!BK12,'DETAIL SALES'!$AB$10:$AB$7501,"No",'DETAIL SALES'!$C$10:$C$7501,"4") -> 0 | BU12: =COUNTIFS('DETAIL SALES'!$Q$10:$Q$7501,'FILL RATE MANDATORY STOCK'!BK12,'DETAIL SALES'!$AB$10:$AB$7501,"Full",'DETAIL SALES'!$C$10:$C$7501,"5") -> 0 | BV12: =COUNTIFS('DETAIL SALES'!$Q$10:$Q$7501,'FILL RATE MANDATORY STOCK'!BK12,'DETAIL SALES'!$AB$10:$AB$7501,"No",'DETAIL SALES'!$C$10:$C$7501,"5") -> 0 | BW12: =COUNTIFS('DETAIL SALES'!$Q$10:$Q$7501,'FILL RATE MANDATORY STOCK'!BK12,'DETAIL SALES'!$AB$10:$AB$7501,"Full",'DETAIL SALES'!$C$10:$C$7501,"6") -> 0 | BX12: =COUNTIFS('DETAIL SALES'!$Q$10:$Q$7501,'FILL RATE MANDATORY STOCK'!BK12,'DETAIL SALES'!$AB$10:$AB$7501,"No",'DETAIL SALES'!$C$10:$C$7501,"6") -> 0 | BY12: =COUNTIFS('DETAIL SALES'!$Q$10:$Q$7501,'FILL RATE MANDATORY STOCK'!BK12,'DETAIL SALES'!$AB$10:$AB$7501,"Full",'DETAIL SALES'!$C$10:$C$7501,"7") -> 0 | BZ12: =COUNTIFS('DETAIL SALES'!$Q$10:$Q$7501,'FILL RATE MANDATORY STOCK'!BK12,'DETAIL SALES'!$AB$10:$AB$7501,"No",'DETAIL SALES'!$C$10:$C$7501,"7") -> 0 | CA12: =COUNTIFS('DETAIL SALES'!$Q$10:$Q$7501,'FILL RATE MANDATORY STOCK'!BK12,'DETAIL SALES'!$AB$10:$AB$7501,"Full",'DETAIL SALES'!$C$10:$C$7501,"8") -> 0 | CB12: =COUNTIFS('DETAIL SALES'!$Q$10:$Q$7501,'FILL RATE MANDATORY STOCK'!BK12,'DETAIL SALES'!$AB$10:$AB$7501,"No",'DETAIL SALES'!$C$10:$C$7501,"8") -> 0 | CC12: =COUNTIFS('DETAIL SALES'!$Q$10:$Q$7501,'FILL RATE MANDATORY STOCK'!BK12,'DETAIL SALES'!$AB$10:$AB$7501,"Full",'DETAIL SALES'!$C$10:$C$7501,"9") -> 0 | CD12: =COUNTIFS('DETAIL SALES'!$Q$10:$Q$7501,'FILL RATE MANDATORY STOCK'!BK12,'DETAIL SALES'!$AB$10:$AB$7501,"No",'DETAIL SALES'!$C$10:$C$7501,"9") -> 0 | CE12: =COUNTIFS('DETAIL SALES'!$Q$10:$Q$7501,'FILL RATE MANDATORY STOCK'!BK12,'DETAIL SALES'!$AB$10:$AB$7501,"Full",'DETAIL SALES'!$C$10:$C$7501,"10") -> 0 | CF12: =COUNTIFS('DETAIL SALES'!$Q$10:$Q$7501,'FILL RATE MANDATORY STOCK'!BK12,'DETAIL SALES'!$AB$10:$AB$7501,"No",'DETAIL SALES'!$C$10:$C$7501,"10") -> 0 | CG12: =COUNTIFS('DETAIL SALES'!$Q$10:$Q$7501,'FILL RATE MANDATORY STOCK'!BK12,'DETAIL SALES'!$AB$10:$AB$7501,"Full",'DETAIL SALES'!$C$10:$C$7501,"11") -> 0 | CH12: =COUNTIFS('DETAIL SALES'!$Q$10:$Q$7501,'FILL RATE MANDATORY STOCK'!BK12,'DETAIL SALES'!$AB$10:$AB$7501,"No",'DETAIL SALES'!$C$10:$C$7501,"11") -> 0 | CI12: =COUNTIFS('DETAIL SALES'!$Q$10:$Q$7501,'FILL RATE MANDATORY STOCK'!BK12,'DETAIL SALES'!$AB$10:$AB$7501,"Full",'DETAIL SALES'!$C$10:$C$7501,"12") -> 0 | CJ12: =COUNTIFS('DETAIL SALES'!$Q$10:$Q$7501,'FILL RATE MANDATORY STOCK'!BK12,'DETAIL SALES'!$AB$10:$AB$7501,"No",'DETAIL SALES'!$C$10:$C$7501,"12") -> 0 | CK12: =COUNTIFS('DETAIL SALES'!$Q$10:$Q$7501,'FILL RATE MANDATORY STOCK'!BK12,'DETAIL SALES'!$AB$10:$AB$7501,"Full",'DETAIL SALES'!$C$10:$C$7501,"13") -> 0 | CL12: =COUNTIFS('DETAIL SALES'!$Q$10:$Q$7501,'FILL RATE MANDATORY STOCK'!BK12,'DETAIL SALES'!$AB$10:$AB$7501,"No",'DETAIL SALES'!$C$10:$C$7501,"13") -> 0 | CM12: =COUNTIFS('DETAIL SALES'!$Q$10:$Q$7501,'FILL RATE MANDATORY STOCK'!BK12,'DETAIL SALES'!$AB$10:$AB$7501,"Full",'DETAIL SALES'!$C$10:$C$7501,"14") -> 0 | CN12: =COUNTIFS('DETAIL SALES'!$Q$10:$Q$7501,'FILL RATE MANDATORY STOCK'!BK12,'DETAIL SALES'!$AB$10:$AB$7501,"No",'DETAIL SALES'!$C$10:$C$7501,"14") -> 0 | CO12: =COUNTIFS('DETAIL SALES'!$Q$10:$Q$7501,'FILL RATE MANDATORY STOCK'!BK12,'DETAIL SALES'!$AB$10:$AB$7501,"Full",'DETAIL SALES'!$C$10:$C$7501,"15") -> 0 | CP12: =COUNTIFS('DETAIL SALES'!$Q$10:$Q$7501,'FILL RATE MANDATORY STOCK'!BK12,'DETAIL SALES'!$AB$10:$AB$7501,"No",'DETAIL SALES'!$C$10:$C$7501,"15") -> 0 | CQ12: =COUNTIFS('DETAIL SALES'!$Q$10:$Q$7501,'FILL RATE MANDATORY STOCK'!BK12,'DETAIL SALES'!$AB$10:$AB$7501,"Full",'DETAIL SALES'!$C$10:$C$7501,"16") -> 0 | CR12: =COUNTIFS('DETAIL SALES'!$Q$10:$Q$7501,'FILL RATE MANDATORY STOCK'!BK12,'DETAIL SALES'!$AB$10:$AB$7501,"No",'DETAIL SALES'!$C$10:$C$7501,"16") -> 0 | CS12: =COUNTIFS('DETAIL SALES'!$Q$10:$Q$7501,'FILL RATE MANDATORY STOCK'!BK12,'DETAIL SALES'!$AB$10:$AB$7501,"Full",'DETAIL SALES'!$C$10:$C$7501,"17") -> 0 | CT12: =COUNTIFS('DETAIL SALES'!$Q$10:$Q$7501,'FILL RATE MANDATORY STOCK'!BK12,'DETAIL SALES'!$AB$10:$AB$7501,"No",'DETAIL SALES'!$C$10:$C$7501,"17") -> 0 | CU12: =COUNTIFS('DETAIL SALES'!$Q$10:$Q$7501,'FILL RATE MANDATORY STOCK'!BK12,'DETAIL SALES'!$AB$10:$AB$7501,"Full",'DETAIL SALES'!$C$10:$C$7501,"18") -> 0 | CV12: =COUNTIFS('DETAIL SALES'!$Q$10:$Q$7501,'FILL RATE MANDATORY STOCK'!BK12,'DETAIL SALES'!$AB$10:$AB$7501,"No",'DETAIL SALES'!$C$10:$C$7501,"18") -> 0 | CW12: =COUNTIFS('DETAIL SALES'!$Q$10:$Q$7501,'FILL RATE MANDATORY STOCK'!BK12,'DETAIL SALES'!$AB$10:$AB$7501,"Full",'DETAIL SALES'!$C$10:$C$7501,"19") -> 0 | CX12: =COUNTIFS('DETAIL SALES'!$Q$10:$Q$7501,'FILL RATE MANDATORY STOCK'!BK12,'DETAIL SALES'!$AB$10:$AB$7501,"No",'DETAIL SALES'!$C$10:$C$7501,"19") -> 0 | CY12: =COUNTIFS('DETAIL SALES'!$Q$10:$Q$7501,'FILL RATE MANDATORY STOCK'!BK12,'DETAIL SALES'!$AB$10:$AB$7501,"Full",'DETAIL SALES'!$C$10:$C$7501,"20") -> 0 | CZ12: =COUNTIFS('DETAIL SALES'!$Q$10:$Q$7501,'FILL RATE MANDATORY STOCK'!BK12,'DETAIL SALES'!$AB$10:$AB$7501,"No",'DETAIL SALES'!$C$10:$C$7501,"20") -> 0 | DA12: =COUNTIFS('DETAIL SALES'!$Q$10:$Q$7501,'FILL RATE MANDATORY STOCK'!BK12,'DETAIL SALES'!$AB$10:$AB$7501,"Full",'DETAIL SALES'!$C$10:$C$7501,"21") -> 0 | DB12: =COUNTIFS('DETAIL SALES'!$Q$10:$Q$7501,'FILL RATE MANDATORY STOCK'!BK12,'DETAIL SALES'!$AB$10:$AB$7501,"No",'DETAIL SALES'!$C$10:$C$7501,"21") -> 0 | DC12: =COUNTIFS('DETAIL SALES'!$Q$10:$Q$7501,'FILL RATE MANDATORY STOCK'!BK12,'DETAIL SALES'!$AB$10:$AB$7501,"Full",'DETAIL SALES'!$C$10:$C$7501,"22") -> 0 | DD12: =COUNTIFS('DETAIL SALES'!$Q$10:$Q$7501,'FILL RATE MANDATORY STOCK'!BK12,'DETAIL SALES'!$AB$10:$AB$7501,"No",'DETAIL SALES'!$C$10:$C$7501,"22") -> 0 | DE12: =COUNTIFS('DETAIL SALES'!$Q$10:$Q$7501,'FILL RATE MANDATORY STOCK'!BK12,'DETAIL SALES'!$AB$10:$AB$7501,"Full",'DETAIL SALES'!$C$10:$C$7501,"23") -> 0 | DF12: =COUNTIFS('DETAIL SALES'!$Q$10:$Q$7501,'FILL RATE MANDATORY STOCK'!BK12,'DETAIL SALES'!$AB$10:$AB$7501,"No",'DETAIL SALES'!$C$10:$C$7501,"23") -> 0 | DG12: =COUNTIFS('DETAIL SALES'!$Q$10:$Q$7501,'FILL RATE MANDATORY STOCK'!BK12,'DETAIL SALES'!$AB$10:$AB$7501,"Full",'DETAIL SALES'!$C$10:$C$7501,"24") -> 0 | DH12: =COUNTIFS('DETAIL SALES'!$Q$10:$Q$7501,'FILL RATE MANDATORY STOCK'!BK12,'DETAIL SALES'!$AB$10:$AB$7501,"No",'DETAIL SALES'!$C$10:$C$7501,"24") -> 0 | DI12: =COUNTIFS('DETAIL SALES'!$Q$10:$Q$7501,'FILL RATE MANDATORY STOCK'!BK12,'DETAIL SALES'!$AB$10:$AB$7501,"Full",'DETAIL SALES'!$C$10:$C$7501,"25") -> 0 | DJ12: =COUNTIFS('DETAIL SALES'!$Q$10:$Q$7501,'FILL RATE MANDATORY STOCK'!BK12,'DETAIL SALES'!$AB$10:$AB$7501,"No",'DETAIL SALES'!$C$10:$C$7501,"25") -> 0 | DK12: =COUNTIFS('DETAIL SALES'!$Q$10:$Q$7501,'FILL RATE MANDATORY STOCK'!BK12,'DETAIL SALES'!$AB$10:$AB$7501,"Full",'DETAIL SALES'!$C$10:$C$7501,"26") -> 0 | DL12: =COUNTIFS('DETAIL SALES'!$Q$10:$Q$7501,'FILL RATE MANDATORY STOCK'!BK12,'DETAIL SALES'!$AB$10:$AB$7501,"No",'DETAIL SALES'!$C$10:$C$7501,"26") -> 0 | DM12: =COUNTIFS('DETAIL SALES'!$Q$10:$Q$7501,'FILL RATE MANDATORY STOCK'!BK12,'DETAIL SALES'!$AB$10:$AB$7501,"Full",'DETAIL SALES'!$C$10:$C$7501,"27") -> 0 | DN12: =COUNTIFS('DETAIL SALES'!$Q$10:$Q$7501,'FILL RATE MANDATORY STOCK'!BK12,'DETAIL SALES'!$AB$10:$AB$7501,"No",'DETAIL SALES'!$C$10:$C$7501,"27") -> 0 | DO12: =COUNTIFS('DETAIL SALES'!$Q$10:$Q$7501,'FILL RATE MANDATORY STOCK'!BK12,'DETAIL SALES'!$AB$10:$AB$7501,"Full",'DETAIL SALES'!$C$10:$C$7501,"28") -> 0 | DP12: =COUNTIFS('DETAIL SALES'!$Q$10:$Q$7501,'FILL RATE MANDATORY STOCK'!BK12,'DETAIL SALES'!$AB$10:$AB$7501,"No",'DETAIL SALES'!$C$10:$C$7501,"28") -> 0 | DQ12: =COUNTIFS('DETAIL SALES'!$Q$10:$Q$7501,'FILL RATE MANDATORY STOCK'!BK12,'DETAIL SALES'!$AB$10:$AB$7501,"Full",'DETAIL SALES'!$C$10:$C$7501,"29") -> 0 | DR12: =COUNTIFS('DETAIL SALES'!$Q$10:$Q$7501,'FILL RATE MANDATORY STOCK'!BK12,'DETAIL SALES'!$AB$10:$AB$7501,"No",'DETAIL SALES'!$C$10:$C$7501,"29") -> 0 | DS12: =COUNTIFS('DETAIL SALES'!$Q$10:$Q$7501,'FILL RATE MANDATORY STOCK'!BK12,'DETAIL SALES'!$AB$10:$AB$7501,"Full",'DETAIL SALES'!$C$10:$C$7501,"30") -> 0 | DT12: =COUNTIFS('DETAIL SALES'!$Q$10:$Q$7501,'FILL RATE MANDATORY STOCK'!BK12,'DETAIL SALES'!$AB$10:$AB$7501,"No",'DETAIL SALES'!$C$10:$C$7501,"30") -> 0 | DU12: =COUNTIFS('DETAIL SALES'!$Q$10:$Q$7501,'FILL RATE MANDATORY STOCK'!\,'DETAIL SALES'!$AB$10:$AB$7501,"Full",'DETAIL SALES'!$C$10:$C$7501,"31") -> 0 | DV12: =COUNTIFS('DETAIL SALES'!$Q$10:$Q$7501,'FILL RATE MANDATORY STOCK'!BK12,'DETAIL SALES'!$AB$10:$AB$7501,"No",'DETAIL SALES'!$C$10:$C$7501,"31") -> 0 | DW12: =BM12+BO12+BQ12+BS12+BU12+BW12+BY12+CA12+CC12+CE12+CG12+CI12+CK12+CM12+CO12+CQ12+CS12+CU12+CW12+CY12+DA12+DC12+DE12+DG12+DI12+DK12+DM12+DO12+DQ12+DS12+DU12 -> 0 | DX12: =BN12+BP12+BR12+BT12+BV12+BX12+BZ12+CB12+CD12+CF12+CH12+CJ12+CL12+CN12+CP12+CR12+CT12+CV12+CX12+CZ12+DB12+DD12+DF12+DH12+DJ12+DL12+DN12+DP12+DR12+DT12+DV12 -> 0 | DY12: =DW12+DX12 -> 0 | DZ12: =DW12/DY12 -> #DIV/0!
A13: 4 | C13: =DAY(B13) -> 0 | D13: =MONTH(B13) -> 1 | E13: =YEAR(B13) -> 1900 | Y13: =X13*U13 -> 0 | Z13: =Y13*1.1 -> 0 | AB13: =IF(S13="","",IF(S13-U13=0,"Full","No")) | AC13: =IF(AND(S13>U13,V13=0),"Lost",IF(AND(S13>U13,V13<(S13-U13)),"Lost","")) | AD13: =IF(AND(S13>U13,V13=0),S13-U13,IF(AND(S13>U13,V13<(S13-U13)),S13-(U13+V13),"")) | AJ13: 2 | AK13: Consumer Goods | AL13: Indomaret, Alfamart | AN13: PT. ARIMBI JAYA AGUNG | AQ13: Workshop | AR13: =SUMIFS($Y$10:$Y$7501,$N$10:$N$7501,"Workshop",$P$10:$P$7501,"CAT.2") -> 0 | AS13: =SUMIFS($Y$10:$Y$7501,$N$10:$N$7501,"Workshop",$P$10:$P$7501,"CAT.3") -> 0 | AT13: =SUMIFS($Y$10:$Y$7501,$N$10:$N$7501,"Workshop",$P$10:$P$7501,"CAT.5") -> 0 | AU13: =SUMIFS($Y$10:$Y$7501,$N$10:$N$7501,"Workshop",$P$10:$P$7501,"OIL & ACC") -> 0 | AV13: =SUM(AR13:AU13) -> 0 | AW13: =AV13/AV15 -> #DIV/0! | BE13: =BE12+1 -> 2 | BF13: GREASE WHEEL BEARING ( 16 KG ) | BG13: ALL MODEL | BH13: S041040024 | BI13: =VLOOKUP(BH13,#REF!,8,FALSE) -> #REF! | BJ13: 60000 | BK13: 1 | BL13: 0 | BM13: =COUNTIFS('DETAIL SALES'!$Q$10:$Q$7501,'FILL RATE MANDATORY STOCK'!BK13,'DETAIL SALES'!$AB$10:$AB$7501,"Full",'DETAIL SALES'!$C$10:$C$7501,"1") -> 0 | BN13: =COUNTIFS('DETAIL SALES'!$Q$10:$Q$7501,'FILL RATE MANDATORY STOCK'!BK13,'DETAIL SALES'!$AB$10:$AB$7501,"No",'DETAIL SALES'!$C$10:$C$7501,"1") -> 0 | BO13: =COUNTIFS('DETAIL SALES'!$Q$10:$Q$7501,'FILL RATE MANDATORY STOCK'!BK13,'DETAIL SALES'!$AB$10:$AB$7501,"Full",'DETAIL SALES'!$C$10:$C$7501,"2") -> 0 | BP13: =COUNTIFS('DETAIL SALES'!$Q$10:$Q$7501,'FILL RATE MANDATORY STOCK'!BK13,'DETAIL SALES'!$AB$10:$AB$7501,"No",'DETAIL SALES'!$C$10:$C$7501,"2") -> 0 | BQ13: =COUNTIFS('DETAIL SALES'!$Q$10:$Q$7501,'FILL RATE MANDATORY STOCK'!BK13,'DETAIL SALES'!$AB$10:$AB$7501,"Full",'DETAIL SALES'!$C$10:$C$7501,"3") -> 0 | BR13: =COUNTIFS('DETAIL SALES'!$Q$10:$Q$7501,'FILL RATE MANDATORY STOCK'!BK13,'DETAIL SALES'!$AB$10:$AB$7501,"No",'DETAIL SALES'!$C$10:$C$7501,"3") -> 0 | BS13: =COUNTIFS('DETAIL SALES'!$Q$10:$Q$7501,'FILL RATE MANDATORY STOCK'!BK13,'DETAIL SALES'!$AB$10:$AB$7501,"Full",'DETAIL SALES'!$C$10:$C$7501,"4") -> 0 | BT13: =COUNTIFS('DETAIL SALES'!$Q$10:$Q$7501,'FILL RATE MANDATORY STOCK'!BK13,'DETAIL SALES'!$AB$10:$AB$7501,"No",'DETAIL SALES'!$C$10:$C$7501,"4") -> 0 | BU13: =COUNTIFS('DETAIL SALES'!$Q$10:$Q$7501,'FILL RATE MANDATORY STOCK'!BK13,'DETAIL SALES'!$AB$10:$AB$7501,"Full",'DETAIL SALES'!$C$10:$C$7501,"5") -> 0 | BV13: =COUNTIFS('DETAIL SALES'!$Q$10:$Q$7501,'FILL RATE MANDATORY STOCK'!BK13,'DETAIL SALES'!$AB$10:$AB$7501,"No",'DETAIL SALES'!$C$10:$C$7501,"5") -> 0 | BW13: =COUNTIFS('DETAIL SALES'!$Q$10:$Q$7501,'FILL RATE MANDATORY STOCK'!BK13,'DETAIL SALES'!$AB$10:$AB$7501,"Full",'DETAIL SALES'!$C$10:$C$7501,"6") -> 0 | BX13: =COUNTIFS('DETAIL SALES'!$Q$10:$Q$7501,'FILL RATE MANDATORY STOCK'!BK13,'DETAIL SALES'!$AB$10:$AB$7501,"No",'DETAIL SALES'!$C$10:$C$7501,"6") -> 0 | BY13: =COUNTIFS('DETAIL SALES'!$Q$10:$Q$7501,'FILL RATE MANDATORY STOCK'!BK13,'DETAIL SALES'!$AB$10:$AB$7501,"Full",'DETAIL SALES'!$C$10:$C$7501,"7") -> 0 | BZ13: =COUNTIFS('DETAIL SALES'!$Q$10:$Q$7501,'FILL RATE MANDATORY STOCK'!BK13,'DETAIL SALES'!$AB$10:$AB$7501,"No",'DETAIL SALES'!$C$10:$C$7501,"7") -> 0 | CA13: =COUNTIFS('DETAIL SALES'!$Q$10:$Q$7501,'FILL RATE MANDATORY STOCK'!BK13,'DETAIL SALES'!$AB$10:$AB$7501,"Full",'DETAIL SALES'!$C$10:$C$7501,"8") -> 0 | CB13: =COUNTIFS('DETAIL SALES'!$Q$10:$Q$7501,'FILL RATE MANDATORY STOCK'!BK13,'DETAIL SALES'!$AB$10:$AB$7501,"No",'DETAIL SALES'!$C$10:$C$7501,"8") -> 0 | CC13: =COUNTIFS('DETAIL SALES'!$Q$10:$Q$7501,'FILL RATE MANDATORY STOCK'!BK13,'DETAIL SALES'!$AB$10:$AB$7501,"Full",'DETAIL SALES'!$C$10:$C$7501,"9") -> 0 | CD13: =COUNTIFS('DETAIL SALES'!$Q$10:$Q$7501,'FILL RATE MANDATORY STOCK'!BK13,'DETAIL SALES'!$AB$10:$AB$7501,"No",'DETAIL SALES'!$C$10:$C$7501,"9") -> 0 | CE13: =COUNTIFS('DETAIL SALES'!$Q$10:$Q$7501,'FILL RATE MANDATORY STOCK'!BK13,'DETAIL SALES'!$AB$10:$AB$7501,"Full",'DETAIL SALES'!$C$10:$C$7501,"10") -> 0 | CF13: =COUNTIFS('DETAIL SALES'!$Q$10:$Q$7501,'FILL RATE MANDATORY STOCK'!BK13,'DETAIL SALES'!$AB$10:$AB$7501,"No",'DETAIL SALES'!$C$10:$C$7501,"10") -> 0 | CG13: =COUNTIFS('DETAIL SALES'!$Q$10:$Q$7501,'FILL RATE MANDATORY STOCK'!BK13,'DETAIL SALES'!$AB$10:$AB$7501,"Full",'DETAIL SALES'!$C$10:$C$7501,"11") -> 0 | CH13: =COUNTIFS('DETAIL SALES'!$Q$10:$Q$7501,'FILL RATE MANDATORY STOCK'!BK13,'DETAIL SALES'!$AB$10:$AB$7501,"No",'DETAIL SALES'!$C$10:$C$7501,"11") -> 0 | CI13: =COUNTIFS('DETAIL SALES'!$Q$10:$Q$7501,'FILL RATE MANDATORY STOCK'!BK13,'DETAIL SALES'!$AB$10:$AB$7501,"Full",'DETAIL SALES'!$C$10:$C$7501,"12") -> 0 | CJ13: =COUNTIFS('DETAIL SALES'!$Q$10:$Q$7501,'FILL RATE MANDATORY STOCK'!BK13,'DETAIL SALES'!$AB$10:$AB$7501,"No",'DETAIL SALES'!$C$10:$C$7501,"12") -> 0 | CK13: =COUNTIFS('DETAIL SALES'!$Q$10:$Q$7501,'FILL RATE MANDATORY STOCK'!BK13,'DETAIL SALES'!$AB$10:$AB$7501,"Full",'DETAIL SALES'!$C$10:$C$7501,"13") -> 0 | CL13: =COUNTIFS('DETAIL SALES'!$Q$10:$Q$7501,'FILL RATE MANDATORY STOCK'!BK13,'DETAIL SALES'!$AB$10:$AB$7501,"No",'DETAIL SALES'!$C$10:$C$7501,"13") -> 0 | CM13: =COUNTIFS('DETAIL SALES'!$Q$10:$Q$7501,'FILL RATE MANDATORY STOCK'!BK13,'DETAIL SALES'!$AB$10:$AB$7501,"Full",'DETAIL SALES'!$C$10:$C$7501,"14") -> 0 | CN13: =COUNTIFS('DETAIL SALES'!$Q$10:$Q$7501,'FILL RATE MANDATORY STOCK'!BK13,'DETAIL SALES'!$AB$10:$AB$7501,"No",'DETAIL SALES'!$C$10:$C$7501,"14") -> 0 | CO13: =COUNTIFS('DETAIL SALES'!$Q$10:$Q$7501,'FILL RATE MANDATORY STOCK'!BK13,'DETAIL SALES'!$AB$10:$AB$7501,"Full",'DETAIL SALES'!$C$10:$C$7501,"15") -> 0 | CP13: =COUNTIFS('DETAIL SALES'!$Q$10:$Q$7501,'FILL RATE MANDATORY STOCK'!BK13,'DETAIL SALES'!$AB$10:$AB$7501,"No",'DETAIL SALES'!$C$10:$C$7501,"15") -> 0 | CQ13: =COUNTIFS('DETAIL SALES'!$Q$10:$Q$7501,'FILL RATE MANDATORY STOCK'!BK13,'DETAIL SALES'!$AB$10:$AB$7501,"Full",'DETAIL SALES'!$C$10:$C$7501,"16") -> 0 | CR13: =COUNTIFS('DETAIL SALES'!$Q$10:$Q$7501,'FILL RATE MANDATORY STOCK'!BK13,'DETAIL SALES'!$AB$10:$AB$7501,"No",'DETAIL SALES'!$C$10:$C$7501,"16") -> 0 | CS13: =COUNTIFS('DETAIL SALES'!$Q$10:$Q$7501,'FILL RATE MANDATORY STOCK'!BK13,'DETAIL SALES'!$AB$10:$AB$7501,"Full",'DETAIL SALES'!$C$10:$C$7501,"17") -> 0 | CT13: =COUNTIFS('DETAIL SALES'!$Q$10:$Q$7501,'FILL RATE MANDATORY STOCK'!BK13,'DETAIL SALES'!$AB$10:$AB$7501,"No",'DETAIL SALES'!$C$10:$C$7501,"17") -> 0 | CU13: =COUNTIFS('DETAIL SALES'!$Q$10:$Q$7501,'FILL RATE MANDATORY STOCK'!BK13,'DETAIL SALES'!$AB$10:$AB$7501,"Full",'DETAIL SALES'!$C$10:$C$7501,"18") -> 0 | CV13: =COUNTIFS('DETAIL SALES'!$Q$10:$Q$7501,'FILL RATE MANDATORY STOCK'!BK13,'DETAIL SALES'!$AB$10:$AB$7501,"No",'DETAIL SALES'!$C$10:$C$7501,"18") -> 0 | CW13: =COUNTIFS('DETAIL SALES'!$Q$10:$Q$7501,'FILL RATE MANDATORY STOCK'!BK13,'DETAIL SALES'!$AB$10:$AB$7501,"Full",'DETAIL SALES'!$C$10:$C$7501,"19") -> 0 | CX13: =COUNTIFS('DETAIL SALES'!$Q$10:$Q$7501,'FILL RATE MANDATORY STOCK'!BK13,'DETAIL SALES'!$AB$10:$AB$7501,"No",'DETAIL SALES'!$C$10:$C$7501,"19") -> 0 | CY13: =COUNTIFS('DETAIL SALES'!$Q$10:$Q$7501,'FILL RATE MANDATORY STOCK'!BK13,'DETAIL SALES'!$AB$10:$AB$7501,"Full",'DETAIL SALES'!$C$10:$C$7501,"20") -> 0 | CZ13: =COUNTIFS('DETAIL SALES'!$Q$10:$Q$7501,'FILL RATE MANDATORY STOCK'!BK13,'DETAIL SALES'!$AB$10:$AB$7501,"No",'DETAIL SALES'!$C$10:$C$7501,"20") -> 0 | DA13: =COUNTIFS('DETAIL SALES'!$Q$10:$Q$7501,'FILL RATE MANDATORY STOCK'!BK13,'DETAIL SALES'!$AB$10:$AB$7501,"Full",'DETAIL SALES'!$C$10:$C$7501,"21") -> 0 | DB13: =COUNTIFS('DETAIL SALES'!$Q$10:$Q$7501,'FILL RATE MANDATORY STOCK'!BK13,'DETAIL SALES'!$AB$10:$AB$7501,"No",'DETAIL SALES'!$C$10:$C$7501,"21") -> 0 | DC13: =COUNTIFS('DETAIL SALES'!$Q$10:$Q$7501,'FILL RATE MANDATORY STOCK'!BK13,'DETAIL SALES'!$AB$10:$AB$7501,"Full",'DETAIL SALES'!$C$10:$C$7501,"22") -> 0 | DD13: =COUNTIFS('DETAIL SALES'!$Q$10:$Q$7501,'FILL RATE MANDATORY STOCK'!BK13,'DETAIL SALES'!$AB$10:$AB$7501,"No",'DETAIL SALES'!$C$10:$C$7501,"22") -> 0 | DE13: =COUNTIFS('DETAIL SALES'!$Q$10:$Q$7501,'FILL RATE MANDATORY STOCK'!BK13,'DETAIL SALES'!$AB$10:$AB$7501,"Full",'DETAIL SALES'!$C$10:$C$7501,"23") -> 0 | DF13: =COUNTIFS('DETAIL SALES'!$Q$10:$Q$7501,'FILL RATE MANDATORY STOCK'!BK13,'DETAIL SALES'!$AB$10:$AB$7501,"No",'DETAIL SALES'!$C$10:$C$7501,"23") -> 0 | DG13: =COUNTIFS('DETAIL SALES'!$Q$10:$Q$7501,'FILL RATE MANDATORY STOCK'!BK13,'DETAIL SALES'!$AB$10:$AB$7501,"Full",'DETAIL SALES'!$C$10:$C$7501,"24") -> 0 | DH13: =COUNTIFS('DETAIL SALES'!$Q$10:$Q$7501,'FILL RATE MANDATORY STOCK'!BK13,'DETAIL SALES'!$AB$10:$AB$7501,"No",'DETAIL SALES'!$C$10:$C$7501,"24") -> 0 | DI13: =COUNTIFS('DETAIL SALES'!$Q$10:$Q$7501,'FILL RATE MANDATORY STOCK'!BK13,'DETAIL SALES'!$AB$10:$AB$7501,"Full",'DETAIL SALES'!$C$10:$C$7501,"25") -> 0 | DJ13: =COUNTIFS('DETAIL SALES'!$Q$10:$Q$7501,'FILL RATE MANDATORY STOCK'!BK13,'DETAIL SALES'!$AB$10:$AB$7501,"No",'DETAIL SALES'!$C$10:$C$7501,"25") -> 0 | DK13: =COUNTIFS('DETAIL SALES'!$Q$10:$Q$7501,'FILL RATE MANDATORY STOCK'!BK13,'DETAIL SALES'!$AB$10:$AB$7501,"Full",'DETAIL SALES'!$C$10:$C$7501,"26") -> 0 | DL13: =COUNTIFS('DETAIL SALES'!$Q$10:$Q$7501,'FILL RATE MANDATORY STOCK'!BK13,'DETAIL SALES'!$AB$10:$AB$7501,"No",'DETAIL SALES'!$C$10:$C$7501,"26") -> 0 | DM13: =COUNTIFS('DETAIL SALES'!$Q$10:$Q$7501,'FILL RATE MANDATORY STOCK'!BK13,'DETAIL SALES'!$AB$10:$AB$7501,"Full",'DETAIL SALES'!$C$10:$C$7501,"27") -> 0 | DN13: =COUNTIFS('DETAIL SALES'!$Q$10:$Q$7501,'FILL RATE MANDATORY STOCK'!BK13,'DETAIL SALES'!$AB$10:$AB$7501,"No",'DETAIL SALES'!$C$10:$C$7501,"27") -> 0 | DO13: =COUNTIFS('DETAIL SALES'!$Q$10:$Q$7501,'FILL RATE MANDATORY STOCK'!BK13,'DETAIL SALES'!$AB$10:$AB$7501,"Full",'DETAIL SALES'!$C$10:$C$7501,"28") -> 0 | DP13: =COUNTIFS('DETAIL SALES'!$Q$10:$Q$7501,'FILL RATE MANDATORY STOCK'!BK13,'DETAIL SALES'!$AB$10:$AB$7501,"No",'DETAIL SALES'!$C$10:$C$7501,"28") -> 0 | DQ13: =COUNTIFS('DETAIL SALES'!$Q$10:$Q$7501,'FILL RATE MANDATORY STOCK'!BK13,'DETAIL SALES'!$AB$10:$AB$7501,"Full",'DETAIL SALES'!$C$10:$C$7501,"29") -> 0 | DR13: =COUNTIFS('DETAIL SALES'!$Q$10:$Q$7501,'FILL RATE MANDATORY STOCK'!BK13,'DETAIL SALES'!$AB$10:$AB$7501,"No",'DETAIL SALES'!$C$10:$C$7501,"29") -> 0 | DS13: =COUNTIFS('DETAIL SALES'!$Q$10:$Q$7501,'FILL RATE MANDATORY STOCK'!BK13,'DETAIL SALES'!$AB$10:$AB$7501,"Full",'DETAIL SALES'!$C$10:$C$7501,"30") -> 0 | DT13: =COUNTIFS('DETAIL SALES'!$Q$10:$Q$7501,'FILL RATE MANDATORY STOCK'!BK13,'DETAIL SALES'!$AB$10:$AB$7501,"No",'DETAIL SALES'!$C$10:$C$7501,"30") -> 0 | DU13: =COUNTIFS('DETAIL SALES'!$Q$10:$Q$7501,'FILL RATE MANDATORY STOCK'!\,'DETAIL SALES'!$AB$10:$AB$7501,"Full",'DETAIL SALES'!$C$10:$C$7501,"31") -> 0 | DV13: =COUNTIFS('DETAIL SALES'!$Q$10:$Q$7501,'FILL RATE MANDATORY STOCK'!BK13,'DETAIL SALES'!$AB$10:$AB$7501,"No",'DETAIL SALES'!$C$10:$C$7501,"31") -> 0 | DW13: =BM13+BO13+BQ13+BS13+BU13+BW13+BY13+CA13+CC13+CE13+CG13+CI13+CK13+CM13+CO13+CQ13+CS13+CU13+CW13+CY13+DA13+DC13+DE13+DG13+DI13+DK13+DM13+DO13+DQ13+DS13+DU13 -> 0 | DX13: =BN13+BP13+BR13+BT13+BV13+BX13+BZ13+CB13+CD13+CF13+CH13+CJ13+CL13+CN13+CP13+CR13+CT13+CV13+CX13+CZ13+DB13+DD13+DF13+DH13+DJ13+DL13+DN13+DP13+DR13+DT13+DV13 -> 0 | DY13: =DW13+DX13 -> 0 | DZ13: =DW13/DY13 -> #DIV/0!
A14: 5 | C14: =DAY(B14) -> 0 | D14: =MONTH(B14) -> 1 | E14: =YEAR(B14) -> 1900 | Y14: =X14*U14 -> 0 | Z14: =Y14*1.1 -> 0 | AB14: =IF(S14="","",IF(S14-U14=0,"Full","No")) | AC14: =IF(AND(S14>U14,V14=0),"Lost",IF(AND(S14>U14,V14<(S14-U14)),"Lost","")) | AD14: =IF(AND(S14>U14,V14=0),S14-U14,IF(AND(S14>U14,V14<(S14-U14)),S14-(U14+V14),"")) | AJ14: 3 | AK14: Government | AL14: Pemerintah Pusat & Daerah | AN14: PT. ARISTA JAYA NIAGA | AQ14: Partshop | AR14: =SUMIFS($Y$10:$Y$7501,$N$10:$N$7501,"Partshop",$P$10:$P$7501,"CAT.2") -> 0 | AS14: =SUMIFS($Y$10:$Y$7501,$N$10:$N$7501,"Partshop",$P$10:$P$7501,"CAT.3") -> 0 | AT14: =SUMIFS($Y$10:$Y$7501,$N$10:$N$7501,"Partshop",$P$10:$P$7501,"CAT.5") -> 0 | AU14: =SUMIFS($Y$10:$Y$7501,$N$10:$N$7501,"Partshop",$P$10:$P$7501,"OIL & ACC") -> 0 | AV14: =SUM(AR14:AU14) -> 0 | AW14: =AV14/AV15 -> #DIV/0! | BE14: =BE13+1 -> 3 | BF14: Hino Genuine Power Steering Oil ( HGPSF) 20 ltr | BG14: ALL MODEL | BH14: 0410721042 | BI14: =VLOOKUP(BH14,#REF!,8,FALSE) -> #REF! | BJ14: 5.000 & 60.000 | BK14: 1 | BL14: 0 | BM14: =COUNTIFS('DETAIL SALES'!$Q$10:$Q$7501,'FILL RATE MANDATORY STOCK'!BK14,'DETAIL SALES'!$AB$10:$AB$7501,"Full",'DETAIL SALES'!$C$10:$C$7501,"1") -> 0 | BN14: =COUNTIFS('DETAIL SALES'!$Q$10:$Q$7501,'FILL RATE MANDATORY STOCK'!BK14,'DETAIL SALES'!$AB$10:$AB$7501,"No",'DETAIL SALES'!$C$10:$C$7501,"1") -> 0 | BO14: =COUNTIFS('DETAIL SALES'!$Q$10:$Q$7501,'FILL RATE MANDATORY STOCK'!BK14,'DETAIL SALES'!$AB$10:$AB$7501,"Full",'DETAIL SALES'!$C$10:$C$7501,"2") -> 0 | BP14: =COUNTIFS('DETAIL SALES'!$Q$10:$Q$7501,'FILL RATE MANDATORY STOCK'!BK14,'DETAIL SALES'!$AB$10:$AB$7501,"No",'DETAIL SALES'!$C$10:$C$7501,"2") -> 0 | BQ14: =COUNTIFS('DETAIL SALES'!$Q$10:$Q$7501,'FILL RATE MANDATORY STOCK'!BK14,'DETAIL SALES'!$AB$10:$AB$7501,"Full",'DETAIL SALES'!$C$10:$C$7501,"3") -> 0 | BR14: =COUNTIFS('DETAIL SALES'!$Q$10:$Q$7501,'FILL RATE MANDATORY STOCK'!BK14,'DETAIL SALES'!$AB$10:$AB$7501,"No",'DETAIL SALES'!$C$10:$C$7501,"3") -> 0 | BS14: =COUNTIFS('DETAIL SALES'!$Q$10:$Q$7501,'FILL RATE MANDATORY STOCK'!BK14,'DETAIL SALES'!$AB$10:$AB$7501,"Full",'DETAIL SALES'!$C$10:$C$7501,"4") -> 0 | BT14: =COUNTIFS('DETAIL SALES'!$Q$10:$Q$7501,'FILL RATE MANDATORY STOCK'!BK14,'DETAIL SALES'!$AB$10:$AB$7501,"No",'DETAIL SALES'!$C$10:$C$7501,"4") -> 0 | BU14: =COUNTIFS('DETAIL SALES'!$Q$10:$Q$7501,'FILL RATE MANDATORY STOCK'!BK14,'DETAIL SALES'!$AB$10:$AB$7501,"Full",'DETAIL SALES'!$C$10:$C$7501,"5") -> 0 | BV14: =COUNTIFS('DETAIL SALES'!$Q$10:$Q$7501,'FILL RATE MANDATORY STOCK'!BK14,'DETAIL SALES'!$AB$10:$AB$7501,"No",'DETAIL SALES'!$C$10:$C$7501,"5") -> 0 | BW14: =COUNTIFS('DETAIL SALES'!$Q$10:$Q$7501,'FILL RATE MANDATORY STOCK'!BK14,'DETAIL SALES'!$AB$10:$AB$7501,"Full",'DETAIL SALES'!$C$10:$C$7501,"6") -> 0 | BX14: =COUNTIFS('DETAIL SALES'!$Q$10:$Q$7501,'FILL RATE MANDATORY STOCK'!BK14,'DETAIL SALES'!$AB$10:$AB$7501,"No",'DETAIL SALES'!$C$10:$C$7501,"6") -> 0 | BY14: =COUNTIFS('DETAIL SALES'!$Q$10:$Q$7501,'FILL RATE MANDATORY STOCK'!BK14,'DETAIL SALES'!$AB$10:$AB$7501,"Full",'DETAIL SALES'!$C$10:$C$7501,"7") -> 0 | BZ14: =COUNTIFS('DETAIL SALES'!$Q$10:$Q$7501,'FILL RATE MANDATORY STOCK'!BK14,'DETAIL SALES'!$AB$10:$AB$7501,"No",'DETAIL SALES'!$C$10:$C$7501,"7") -> 0 | CA14: =COUNTIFS('DETAIL SALES'!$Q$10:$Q$7501,'FILL RATE MANDATORY STOCK'!BK14,'DETAIL SALES'!$AB$10:$AB$7501,"Full",'DETAIL SALES'!$C$10:$C$7501,"8") -> 0 | CB14: =COUNTIFS('DETAIL SALES'!$Q$10:$Q$7501,'FILL RATE MANDATORY STOCK'!BK14,'DETAIL SALES'!$AB$10:$AB$7501,"No",'DETAIL SALES'!$C$10:$C$7501,"8") -> 0 | CC14: =COUNTIFS('DETAIL SALES'!$Q$10:$Q$7501,'FILL RATE MANDATORY STOCK'!BK14,'DETAIL SALES'!$AB$10:$AB$7501,"Full",'DETAIL SALES'!$C$10:$C$7501,"9") -> 0 | CD14: =COUNTIFS('DETAIL SALES'!$Q$10:$Q$7501,'FILL RATE MANDATORY STOCK'!BK14,'DETAIL SALES'!$AB$10:$AB$7501,"No",'DETAIL SALES'!$C$10:$C$7501,"9") -> 0 | CE14: =COUNTIFS('DETAIL SALES'!$Q$10:$Q$7501,'FILL RATE MANDATORY STOCK'!BK14,'DETAIL SALES'!$AB$10:$AB$7501,"Full",'DETAIL SALES'!$C$10:$C$7501,"10") -> 0 | CF14: =COUNTIFS('DETAIL SALES'!$Q$10:$Q$7501,'FILL RATE MANDATORY STOCK'!BK14,'DETAIL SALES'!$AB$10:$AB$7501,"No",'DETAIL SALES'!$C$10:$C$7501,"10") -> 0 | CG14: =COUNTIFS('DETAIL SALES'!$Q$10:$Q$7501,'FILL RATE MANDATORY STOCK'!BK14,'DETAIL SALES'!$AB$10:$AB$7501,"Full",'DETAIL SALES'!$C$10:$C$7501,"11") -> 0 | CH14: =COUNTIFS('DETAIL SALES'!$Q$10:$Q$7501,'FILL RATE MANDATORY STOCK'!BK14,'DETAIL SALES'!$AB$10:$AB$7501,"No",'DETAIL SALES'!$C$10:$C$7501,"11") -> 0 | CI14: =COUNTIFS('DETAIL SALES'!$Q$10:$Q$7501,'FILL RATE MANDATORY STOCK'!BK14,'DETAIL SALES'!$AB$10:$AB$7501,"Full",'DETAIL SALES'!$C$10:$C$7501,"12") -> 0 | CJ14: =COUNTIFS('DETAIL SALES'!$Q$10:$Q$7501,'FILL RATE MANDATORY STOCK'!BK14,'DETAIL SALES'!$AB$10:$AB$7501,"No",'DETAIL SALES'!$C$10:$C$7501,"12") -> 0 | CK14: =COUNTIFS('DETAIL SALES'!$Q$10:$Q$7501,'FILL RATE MANDATORY STOCK'!BK14,'DETAIL SALES'!$AB$10:$AB$7501,"Full",'DETAIL SALES'!$C$10:$C$7501,"13") -> 0 | CL14: =COUNTIFS('DETAIL SALES'!$Q$10:$Q$7501,'FILL RATE MANDATORY STOCK'!BK14,'DETAIL SALES'!$AB$10:$AB$7501,"No",'DETAIL SALES'!$C$10:$C$7501,"13") -> 0 | CM14: =COUNTIFS('DETAIL SALES'!$Q$10:$Q$7501,'FILL RATE MANDATORY STOCK'!BK14,'DETAIL SALES'!$AB$10:$AB$7501,"Full",'DETAIL SALES'!$C$10:$C$7501,"14") -> 0 | CN14: =COUNTIFS('DETAIL SALES'!$Q$10:$Q$7501,'FILL RATE MANDATORY STOCK'!BK14,'DETAIL SALES'!$AB$10:$AB$7501,"No",'DETAIL SALES'!$C$10:$C$7501,"14") -> 0 | CO14: =COUNTIFS('DETAIL SALES'!$Q$10:$Q$7501,'FILL RATE MANDATORY STOCK'!BK14,'DETAIL SALES'!$AB$10:$AB$7501,"Full",'DETAIL SALES'!$C$10:$C$7501,"15") -> 0 | CP14: =COUNTIFS('DETAIL SALES'!$Q$10:$Q$7501,'FILL RATE MANDATORY STOCK'!BK14,'DETAIL SALES'!$AB$10:$AB$7501,"No",'DETAIL SALES'!$C$10:$C$7501,"15") -> 0 | CQ14: =COUNTIFS('DETAIL SALES'!$Q$10:$Q$7501,'FILL RATE MANDATORY STOCK'!BK14,'DETAIL SALES'!$AB$10:$AB$7501,"Full",'DETAIL SALES'!$C$10:$C$7501,"16") -> 0 | CR14: =COUNTIFS('DETAIL SALES'!$Q$10:$Q$7501,'FILL RATE MANDATORY STOCK'!BK14,'DETAIL SALES'!$AB$10:$AB$7501,"No",'DETAIL SALES'!$C$10:$C$7501,"16") -> 0 | CS14: =COUNTIFS('DETAIL SALES'!$Q$10:$Q$7501,'FILL RATE MANDATORY STOCK'!BK14,'DETAIL SALES'!$AB$10:$AB$7501,"Full",'DETAIL SALES'!$C$10:$C$7501,"17") -> 0 | CT14: =COUNTIFS('DETAIL SALES'!$Q$10:$Q$7501,'FILL RATE MANDATORY STOCK'!BK14,'DETAIL SALES'!$AB$10:$AB$7501,"No",'DETAIL SALES'!$C$10:$C$7501,"17") -> 0 | CU14: =COUNTIFS('DETAIL SALES'!$Q$10:$Q$7501,'FILL RATE MANDATORY STOCK'!BK14,'DETAIL SALES'!$AB$10:$AB$7501,"Full",'DETAIL SALES'!$C$10:$C$7501,"18") -> 0 | CV14: =COUNTIFS('DETAIL SALES'!$Q$10:$Q$7501,'FILL RATE MANDATORY STOCK'!BK14,'DETAIL SALES'!$AB$10:$AB$7501,"No",'DETAIL SALES'!$C$10:$C$7501,"18") -> 0 | CW14: =COUNTIFS('DETAIL SALES'!$Q$10:$Q$7501,'FILL RATE MANDATORY STOCK'!BK14,'DETAIL SALES'!$AB$10:$AB$7501,"Full",'DETAIL SALES'!$C$10:$C$7501,"19") -> 0 | CX14: =COUNTIFS('DETAIL SALES'!$Q$10:$Q$7501,'FILL RATE MANDATORY STOCK'!BK14,'DETAIL SALES'!$AB$10:$AB$7501,"No",'DETAIL SALES'!$C$10:$C$7501,"19") -> 0 | CY14: =COUNTIFS('DETAIL SALES'!$Q$10:$Q$7501,'FILL RATE MANDATORY STOCK'!BK14,'DETAIL SALES'!$AB$10:$AB$7501,"Full",'DETAIL SALES'!$C$10:$C$7501,"20") -> 0 | CZ14: =COUNTIFS('DETAIL SALES'!$Q$10:$Q$7501,'FILL RATE MANDATORY STOCK'!BK14,'DETAIL SALES'!$AB$10:$AB$7501,"No",'DETAIL SALES'!$C$10:$C$7501,"20") -> 0 | DA14: =COUNTIFS('DETAIL SALES'!$Q$10:$Q$7501,'FILL RATE MANDATORY STOCK'!BK14,'DETAIL SALES'!$AB$10:$AB$7501,"Full",'DETAIL SALES'!$C$10:$C$7501,"21") -> 0 | DB14: =COUNTIFS('DETAIL SALES'!$Q$10:$Q$7501,'FILL RATE MANDATORY STOCK'!BK14,'DETAIL SALES'!$AB$10:$AB$7501,"No",'DETAIL SALES'!$C$10:$C$7501,"21") -> 0 | DC14: =COUNTIFS('DETAIL SALES'!$Q$10:$Q$7501,'FILL RATE MANDATORY STOCK'!BK14,'DETAIL SALES'!$AB$10:$AB$7501,"Full",'DETAIL SALES'!$C$10:$C$7501,"22") -> 0 | DD14: =COUNTIFS('DETAIL SALES'!$Q$10:$Q$7501,'FILL RATE MANDATORY STOCK'!BK14,'DETAIL SALES'!$AB$10:$AB$7501,"No",'DETAIL SALES'!$C$10:$C$7501,"22") -> 0 | DE14: =COUNTIFS('DETAIL SALES'!$Q$10:$Q$7501,'FILL RATE MANDATORY STOCK'!BK14,'DETAIL SALES'!$AB$10:$AB$7501,"Full",'DETAIL SALES'!$C$10:$C$7501,"23") -> 0 | DF14: =COUNTIFS('DETAIL SALES'!$Q$10:$Q$7501,'FILL RATE MANDATORY STOCK'!BK14,'DETAIL SALES'!$AB$10:$AB$7501,"No",'DETAIL SALES'!$C$10:$C$7501,"23") -> 0 | DG14: =COUNTIFS('DETAIL SALES'!$Q$10:$Q$7501,'FILL RATE MANDATORY STOCK'!BK14,'DETAIL SALES'!$AB$10:$AB$7501,"Full",'DETAIL SALES'!$C$10:$C$7501,"24") -> 0 | DH14: =COUNTIFS('DETAIL SALES'!$Q$10:$Q$7501,'FILL RATE MANDATORY STOCK'!BK14,'DETAIL SALES'!$AB$10:$AB$7501,"No",'DETAIL SALES'!$C$10:$C$7501,"24") -> 0 | DI14: =COUNTIFS('DETAIL SALES'!$Q$10:$Q$7501,'FILL RATE MANDATORY STOCK'!BK14,'DETAIL SALES'!$AB$10:$AB$7501,"Full",'DETAIL SALES'!$C$10:$C$7501,"25") -> 0 | DJ14: =COUNTIFS('DETAIL SALES'!$Q$10:$Q$7501,'FILL RATE MANDATORY STOCK'!BK14,'DETAIL SALES'!$AB$10:$AB$7501,"No",'DETAIL SALES'!$C$10:$C$7501,"25") -> 0 | DK14: =COUNTIFS('DETAIL SALES'!$Q$10:$Q$7501,'FILL RATE MANDATORY STOCK'!BK14,'DETAIL SALES'!$AB$10:$AB$7501,"Full",'DETAIL SALES'!$C$10:$C$7501,"26") -> 0 | DL14: =COUNTIFS('DETAIL SALES'!$Q$10:$Q$7501,'FILL RATE MANDATORY STOCK'!BK14,'DETAIL SALES'!$AB$10:$AB$7501,"No",'DETAIL SALES'!$C$10:$C$7501,"26") -> 0 | DM14: =COUNTIFS('DETAIL SALES'!$Q$10:$Q$7501,'FILL RATE MANDATORY STOCK'!BK14,'DETAIL SALES'!$AB$10:$AB$7501,"Full",'DETAIL SALES'!$C$10:$C$7501,"27") -> 0 | DN14: =COUNTIFS('DETAIL SALES'!$Q$10:$Q$7501,'FILL RATE MANDATORY STOCK'!BK14,'DETAIL SALES'!$AB$10:$AB$7501,"No",'DETAIL SALES'!$C$10:$C$7501,"27") -> 0 | DO14: =COUNTIFS('DETAIL SALES'!$Q$10:$Q$7501,'FILL RATE MANDATORY STOCK'!BK14,'DETAIL SALES'!$AB$10:$AB$7501,"Full",'DETAIL SALES'!$C$10:$C$7501,"28") -> 0 | DP14: =COUNTIFS('DETAIL SALES'!$Q$10:$Q$7501,'FILL RATE MANDATORY STOCK'!BK14,'DETAIL SALES'!$AB$10:$AB$7501,"No",'DETAIL SALES'!$C$10:$C$7501,"28") -> 0 | DQ14: =COUNTIFS('DETAIL SALES'!$Q$10:$Q$7501,'FILL RATE MANDATORY STOCK'!BK14,'DETAIL SALES'!$AB$10:$AB$7501,"Full",'DETAIL SALES'!$C$10:$C$7501,"29") -> 0 | DR14: =COUNTIFS('DETAIL SALES'!$Q$10:$Q$7501,'FILL RATE MANDATORY STOCK'!BK14,'DETAIL SALES'!$AB$10:$AB$7501,"No",'DETAIL SALES'!$C$10:$C$7501,"29") -> 0 | DS14: =COUNTIFS('DETAIL SALES'!$Q$10:$Q$7501,'FILL RATE MANDATORY STOCK'!BK14,'DETAIL SALES'!$AB$10:$AB$7501,"Full",'DETAIL SALES'!$C$10:$C$7501,"30") -> 0 | DT14: =COUNTIFS('DETAIL SALES'!$Q$10:$Q$7501,'FILL RATE MANDATORY STOCK'!BK14,'DETAIL SALES'!$AB$10:$AB$7501,"No",'DETAIL SALES'!$C$10:$C$7501,"30") -> 0 | DU14: =COUNTIFS('DETAIL SALES'!$Q$10:$Q$7501,'FILL RATE MANDATORY STOCK'!\,'DETAIL SALES'!$AB$10:$AB$7501,"Full",'DETAIL SALES'!$C$10:$C$7501,"31") -> 0 | DV14: =COUNTIFS('DETAIL SALES'!$Q$10:$Q$7501,'FILL RATE MANDATORY STOCK'!BK14,'DETAIL SALES'!$AB$10:$AB$7501,"No",'DETAIL SALES'!$C$10:$C$7501,"31") -> 0 | DW14: =BM14+BO14+BQ14+BS14+BU14+BW14+BY14+CA14+CC14+CE14+CG14+CI14+CK14+CM14+CO14+CQ14+CS14+CU14+CW14+CY14+DA14+DC14+DE14+DG14+DI14+DK14+DM14+DO14+DQ14+DS14+DU14 -> 0 | DX14: =BN14+BP14+BR14+BT14+BV14+BX14+BZ14+CB14+CD14+CF14+CH14+CJ14+CL14+CN14+CP14+CR14+CT14+CV14+CX14+CZ14+DB14+DD14+DF14+DH14+DJ14+DL14+DN14+DP14+DR14+DT14+DV14 -> 0 | DY14: =DW14+DX14 -> 0 | DZ14: =DW14/DY14 -> #DIV/0!
A15: 6 | C15: =DAY(B15) -> 0 | D15: =MONTH(B15) -> 1 | E15: =YEAR(B15) -> 1900 | Y15: =X15*U15 -> 0 | Z15: =Y15*1.1 -> 0 | AB15: =IF(S15="","",IF(S15-U15=0,"Full","No")) | AC15: =IF(AND(S15>U15,V15=0),"Lost",IF(AND(S15>U15,V15<(S15-U15)),"Lost","")) | AD15: =IF(AND(S15>U15,V15=0),S15-U15,IF(AND(S15>U15,V15<(S15-U15)),S15-(U15+V15),"")) | AJ15: 4 | AK15: General Cargo | AL15: FedEx | AN15: PT. ARMINDO PERKASA | AQ15: Total | AR15: =SUM(AR12:AR14) -> 0 | AS15: =SUM(AS12:AS14) -> 0 | AT15: =SUM(AT12:AT14) -> 0 | AU15: =SUM(AU12:AU14) -> 0 | AV15: =SUM(AV12:AV14) -> 0 | AW15: =SUM(AW12:AW14) -> #DIV/0! | BE15: =BE14+1 -> 4 | BF15: HGO Oil | BG15: ALL MODEL | BH15: 041001001 | BI15: =VLOOKUP(BH15,#REF!,8,FALSE) -> #REF! | BJ15: 20000 | BK15: 12.7 | BL15: 0 | BM15: =COUNTIFS('DETAIL SALES'!$Q$10:$Q$7501,'FILL RATE MANDATORY STOCK'!BK15,'DETAIL SALES'!$AB$10:$AB$7501,"Full",'DETAIL SALES'!$C$10:$C$7501,"1") -> 0 | BN15: =COUNTIFS('DETAIL SALES'!$Q$10:$Q$7501,'FILL RATE MANDATORY STOCK'!BK15,'DETAIL SALES'!$AB$10:$AB$7501,"No",'DETAIL SALES'!$C$10:$C$7501,"1") -> 0 | BO15: =COUNTIFS('DETAIL SALES'!$Q$10:$Q$7501,'FILL RATE MANDATORY STOCK'!BK15,'DETAIL SALES'!$AB$10:$AB$7501,"Full",'DETAIL SALES'!$C$10:$C$7501,"2") -> 0 | BP15: =COUNTIFS('DETAIL SALES'!$Q$10:$Q$7501,'FILL RATE MANDATORY STOCK'!BK15,'DETAIL SALES'!$AB$10:$AB$7501,"No",'DETAIL SALES'!$C$10:$C$7501,"2") -> 0 | BQ15: =COUNTIFS('DETAIL SALES'!$Q$10:$Q$7501,'FILL RATE MANDATORY STOCK'!BK15,'DETAIL SALES'!$AB$10:$AB$7501,"Full",'DETAIL SALES'!$C$10:$C$7501,"3") -> 0 | BR15: =COUNTIFS('DETAIL SALES'!$Q$10:$Q$7501,'FILL RATE MANDATORY STOCK'!BK15,'DETAIL SALES'!$AB$10:$AB$7501,"No",'DETAIL SALES'!$C$10:$C$7501,"3") -> 0 | BS15: =COUNTIFS('DETAIL SALES'!$Q$10:$Q$7501,'FILL RATE MANDATORY STOCK'!BK15,'DETAIL SALES'!$AB$10:$AB$7501,"Full",'DETAIL SALES'!$C$10:$C$7501,"4") -> 0 | BT15: =COUNTIFS('DETAIL SALES'!$Q$10:$Q$7501,'FILL RATE MANDATORY STOCK'!BK15,'DETAIL SALES'!$AB$10:$AB$7501,"No",'DETAIL SALES'!$C$10:$C$7501,"4") -> 0 | BU15: =COUNTIFS('DETAIL SALES'!$Q$10:$Q$7501,'FILL RATE MANDATORY STOCK'!BK15,'DETAIL SALES'!$AB$10:$AB$7501,"Full",'DETAIL SALES'!$C$10:$C$7501,"5") -> 0 | BV15: =COUNTIFS('DETAIL SALES'!$Q$10:$Q$7501,'FILL RATE MANDATORY STOCK'!BK15,'DETAIL SALES'!$AB$10:$AB$7501,"No",'DETAIL SALES'!$C$10:$C$7501,"5") -> 0 | BW15: =COUNTIFS('DETAIL SALES'!$Q$10:$Q$7501,'FILL RATE MANDATORY STOCK'!BK15,'DETAIL SALES'!$AB$10:$AB$7501,"Full",'DETAIL SALES'!$C$10:$C$7501,"6") -> 0 | BX15: =COUNTIFS('DETAIL SALES'!$Q$10:$Q$7501,'FILL RATE MANDATORY STOCK'!BK15,'DETAIL SALES'!$AB$10:$AB$7501,"No",'DETAIL SALES'!$C$10:$C$7501,"6") -> 0 | BY15: =COUNTIFS('DETAIL SALES'!$Q$10:$Q$7501,'FILL RATE MANDATORY STOCK'!BK15,'DETAIL SALES'!$AB$10:$AB$7501,"Full",'DETAIL SALES'!$C$10:$C$7501,"7") -> 0 | BZ15: =COUNTIFS('DETAIL SALES'!$Q$10:$Q$7501,'FILL RATE MANDATORY STOCK'!BK15,'DETAIL SALES'!$AB$10:$AB$7501,"No",'DETAIL SALES'!$C$10:$C$7501,"7") -> 0 | CA15: =COUNTIFS('DETAIL SALES'!$Q$10:$Q$7501,'FILL RATE MANDATORY STOCK'!BK15,'DETAIL SALES'!$AB$10:$AB$7501,"Full",'DETAIL SALES'!$C$10:$C$7501,"8") -> 0 | CB15: =COUNTIFS('DETAIL SALES'!$Q$10:$Q$7501,'FILL RATE MANDATORY STOCK'!BK15,'DETAIL SALES'!$AB$10:$AB$7501,"No",'DETAIL SALES'!$C$10:$C$7501,"8") -> 0 | CC15: =COUNTIFS('DETAIL SALES'!$Q$10:$Q$7501,'FILL RATE MANDATORY STOCK'!BK15,'DETAIL SALES'!$AB$10:$AB$7501,"Full",'DETAIL SALES'!$C$10:$C$7501,"9") -> 0 | CD15: =COUNTIFS('DETAIL SALES'!$Q$10:$Q$7501,'FILL RATE MANDATORY STOCK'!BK15,'DETAIL SALES'!$AB$10:$AB$7501,"No",'DETAIL SALES'!$C$10:$C$7501,"9") -> 0 | CE15: =COUNTIFS('DETAIL SALES'!$Q$10:$Q$7501,'FILL RATE MANDATORY STOCK'!BK15,'DETAIL SALES'!$AB$10:$AB$7501,"Full",'DETAIL SALES'!$C$10:$C$7501,"10") -> 0 | CF15: =COUNTIFS('DETAIL SALES'!$Q$10:$Q$7501,'FILL RATE MANDATORY STOCK'!BK15,'DETAIL SALES'!$AB$10:$AB$7501,"No",'DETAIL SALES'!$C$10:$C$7501,"10") -> 0 | CG15: =COUNTIFS('DETAIL SALES'!$Q$10:$Q$7501,'FILL RATE MANDATORY STOCK'!BK15,'DETAIL SALES'!$AB$10:$AB$7501,"Full",'DETAIL SALES'!$C$10:$C$7501,"11") -> 0 | CH15: =COUNTIFS('DETAIL SALES'!$Q$10:$Q$7501,'FILL RATE MANDATORY STOCK'!BK15,'DETAIL SALES'!$AB$10:$AB$7501,"No",'DETAIL SALES'!$C$10:$C$7501,"11") -> 0 | CI15: =COUNTIFS('DETAIL SALES'!$Q$10:$Q$7501,'FILL RATE MANDATORY STOCK'!BK15,'DETAIL SALES'!$AB$10:$AB$7501,"Full",'DETAIL SALES'!$C$10:$C$7501,"12") -> 0 | CJ15: =COUNTIFS('DETAIL SALES'!$Q$10:$Q$7501,'FILL RATE MANDATORY STOCK'!BK15,'DETAIL SALES'!$AB$10:$AB$7501,"No",'DETAIL SALES'!$C$10:$C$7501,"12") -> 0 | CK15: =COUNTIFS('DETAIL SALES'!$Q$10:$Q$7501,'FILL RATE MANDATORY STOCK'!BK15,'DETAIL SALES'!$AB$10:$AB$7501,"Full",'DETAIL SALES'!$C$10:$C$7501,"13") -> 0 | CL15: =COUNTIFS('DETAIL SALES'!$Q$10:$Q$7501,'FILL RATE MANDATORY STOCK'!BK15,'DETAIL SALES'!$AB$10:$AB$7501,"No",'DETAIL SALES'!$C$10:$C$7501,"13") -> 0 | CM15: =COUNTIFS('DETAIL SALES'!$Q$10:$Q$7501,'FILL RATE MANDATORY STOCK'!BK15,'DETAIL SALES'!$AB$10:$AB$7501,"Full",'DETAIL SALES'!$C$10:$C$7501,"14") -> 0 | CN15: =COUNTIFS('DETAIL SALES'!$Q$10:$Q$7501,'FILL RATE MANDATORY STOCK'!BK15,'DETAIL SALES'!$AB$10:$AB$7501,"No",'DETAIL SALES'!$C$10:$C$7501,"14") -> 0 | CO15: =COUNTIFS('DETAIL SALES'!$Q$10:$Q$7501,'FILL RATE MANDATORY STOCK'!BK15,'DETAIL SALES'!$AB$10:$AB$7501,"Full",'DETAIL SALES'!$C$10:$C$7501,"15") -> 0 | CP15: =COUNTIFS('DETAIL SALES'!$Q$10:$Q$7501,'FILL RATE MANDATORY STOCK'!BK15,'DETAIL SALES'!$AB$10:$AB$7501,"No",'DETAIL SALES'!$C$10:$C$7501,"15") -> 0 | CQ15: =COUNTIFS('DETAIL SALES'!$Q$10:$Q$7501,'FILL RATE MANDATORY STOCK'!BK15,'DETAIL SALES'!$AB$10:$AB$7501,"Full",'DETAIL SALES'!$C$10:$C$7501,"16") -> 0 | CR15: =COUNTIFS('DETAIL SALES'!$Q$10:$Q$7501,'FILL RATE MANDATORY STOCK'!BK15,'DETAIL SALES'!$AB$10:$AB$7501,"No",'DETAIL SALES'!$C$10:$C$7501,"16") -> 0 | CS15: =COUNTIFS('DETAIL SALES'!$Q$10:$Q$7501,'FILL RATE MANDATORY STOCK'!BK15,'DETAIL SALES'!$AB$10:$AB$7501,"Full",'DETAIL SALES'!$C$10:$C$7501,"17") -> 0 | CT15: =COUNTIFS('DETAIL SALES'!$Q$10:$Q$7501,'FILL RATE MANDATORY STOCK'!BK15,'DETAIL SALES'!$AB$10:$AB$7501,"No",'DETAIL SALES'!$C$10:$C$7501,"17") -> 0 | CU15: =COUNTIFS('DETAIL SALES'!$Q$10:$Q$7501,'FILL RATE MANDATORY STOCK'!BK15,'DETAIL SALES'!$AB$10:$AB$7501,"Full",'DETAIL SALES'!$C$10:$C$7501,"18") -> 0 | CV15: =COUNTIFS('DETAIL SALES'!$Q$10:$Q$7501,'FILL RATE MANDATORY STOCK'!BK15,'DETAIL SALES'!$AB$10:$AB$7501,"No",'DETAIL SALES'!$C$10:$C$7501,"18") -> 0 | CW15: =COUNTIFS('DETAIL SALES'!$Q$10:$Q$7501,'FILL RATE MANDATORY STOCK'!BK15,'DETAIL SALES'!$AB$10:$AB$7501,"Full",'DETAIL SALES'!$C$10:$C$7501,"19") -> 0 | CX15: =COUNTIFS('DETAIL SALES'!$Q$10:$Q$7501,'FILL RATE MANDATORY STOCK'!BK15,'DETAIL SALES'!$AB$10:$AB$7501,"No",'DETAIL SALES'!$C$10:$C$7501,"19") -> 0 | CY15: =COUNTIFS('DETAIL SALES'!$Q$10:$Q$7501,'FILL RATE MANDATORY STOCK'!BK15,'DETAIL SALES'!$AB$10:$AB$7501,"Full",'DETAIL SALES'!$C$10:$C$7501,"20") -> 0 | CZ15: =COUNTIFS('DETAIL SALES'!$Q$10:$Q$7501,'FILL RATE MANDATORY STOCK'!BK15,'DETAIL SALES'!$AB$10:$AB$7501,"No",'DETAIL SALES'!$C$10:$C$7501,"20") -> 0 | DA15: =COUNTIFS('DETAIL SALES'!$Q$10:$Q$7501,'FILL RATE MANDATORY STOCK'!BK15,'DETAIL SALES'!$AB$10:$AB$7501,"Full",'DETAIL SALES'!$C$10:$C$7501,"21") -> 0 | DB15: =COUNTIFS('DETAIL SALES'!$Q$10:$Q$7501,'FILL RATE MANDATORY STOCK'!BK15,'DETAIL SALES'!$AB$10:$AB$7501,"No",'DETAIL SALES'!$C$10:$C$7501,"21") -> 0 | DC15: =COUNTIFS('DETAIL SALES'!$Q$10:$Q$7501,'FILL RATE MANDATORY STOCK'!BK15,'DETAIL SALES'!$AB$10:$AB$7501,"Full",'DETAIL SALES'!$C$10:$C$7501,"22") -> 0 | DD15: =COUNTIFS('DETAIL SALES'!$Q$10:$Q$7501,'FILL RATE MANDATORY STOCK'!BK15,'DETAIL SALES'!$AB$10:$AB$7501,"No",'DETAIL SALES'!$C$10:$C$7501,"22") -> 0 | DE15: =COUNTIFS('DETAIL SALES'!$Q$10:$Q$7501,'FILL RATE MANDATORY STOCK'!BK15,'DETAIL SALES'!$AB$10:$AB$7501,"Full",'DETAIL SALES'!$C$10:$C$7501,"23") -> 0 | DF15: =COUNTIFS('DETAIL SALES'!$Q$10:$Q$7501,'FILL RATE MANDATORY STOCK'!BK15,'DETAIL SALES'!$AB$10:$AB$7501,"No",'DETAIL SALES'!$C$10:$C$7501,"23") -> 0 | DG15: =COUNTIFS('DETAIL SALES'!$Q$10:$Q$7501,'FILL RATE MANDATORY STOCK'!BK15,'DETAIL SALES'!$AB$10:$AB$7501,"Full",'DETAIL SALES'!$C$10:$C$7501,"24") -> 0 | DH15: =COUNTIFS('DETAIL SALES'!$Q$10:$Q$7501,'FILL RATE MANDATORY STOCK'!BK15,'DETAIL SALES'!$AB$10:$AB$7501,"No",'DETAIL SALES'!$C$10:$C$7501,"24") -> 0 | DI15: =COUNTIFS('DETAIL SALES'!$Q$10:$Q$7501,'FILL RATE MANDATORY STOCK'!BK15,'DETAIL SALES'!$AB$10:$AB$7501,"Full",'DETAIL SALES'!$C$10:$C$7501,"25") -> 0 | DJ15: =COUNTIFS('DETAIL SALES'!$Q$10:$Q$7501,'FILL RATE MANDATORY STOCK'!BK15,'DETAIL SALES'!$AB$10:$AB$7501,"No",'DETAIL SALES'!$C$10:$C$7501,"25") -> 0 | DK15: =COUNTIFS('DETAIL SALES'!$Q$10:$Q$7501,'FILL RATE MANDATORY STOCK'!BK15,'DETAIL SALES'!$AB$10:$AB$7501,"Full",'DETAIL SALES'!$C$10:$C$7501,"26") -> 0 | DL15: =COUNTIFS('DETAIL SALES'!$Q$10:$Q$7501,'FILL RATE MANDATORY STOCK'!BK15,'DETAIL SALES'!$AB$10:$AB$7501,"No",'DETAIL SALES'!$C$10:$C$7501,"26") -> 0 | DM15: =COUNTIFS('DETAIL SALES'!$Q$10:$Q$7501,'FILL RATE MANDATORY STOCK'!BK15,'DETAIL SALES'!$AB$10:$AB$7501,"Full",'DETAIL SALES'!$C$10:$C$7501,"27") -> 0 | DN15: =COUNTIFS('DETAIL SALES'!$Q$10:$Q$7501,'FILL RATE MANDATORY STOCK'!BK15,'DETAIL SALES'!$AB$10:$AB$7501,"No",'DETAIL SALES'!$C$10:$C$7501,"27") -> 0 | DO15: =COUNTIFS('DETAIL SALES'!$Q$10:$Q$7501,'FILL RATE MANDATORY STOCK'!BK15,'DETAIL SALES'!$AB$10:$AB$7501,"Full",'DETAIL SALES'!$C$10:$C$7501,"28") -> 0 | DP15: =COUNTIFS('DETAIL SALES'!$Q$10:$Q$7501,'FILL RATE MANDATORY STOCK'!BK15,'DETAIL SALES'!$AB$10:$AB$7501,"No",'DETAIL SALES'!$C$10:$C$7501,"28") -> 0 | DQ15: =COUNTIFS('DETAIL SALES'!$Q$10:$Q$7501,'FILL RATE MANDATORY STOCK'!BK15,'DETAIL SALES'!$AB$10:$AB$7501,"Full",'DETAIL SALES'!$C$10:$C$7501,"29") -> 0 | DR15: =COUNTIFS('DETAIL SALES'!$Q$10:$Q$7501,'FILL RATE MANDATORY STOCK'!BK15,'DETAIL SALES'!$AB$10:$AB$7501,"No",'DETAIL SALES'!$C$10:$C$7501,"29") -> 0 | DS15: =COUNTIFS('DETAIL SALES'!$Q$10:$Q$7501,'FILL RATE MANDATORY STOCK'!BK15,'DETAIL SALES'!$AB$10:$AB$7501,"Full",'DETAIL SALES'!$C$10:$C$7501,"30") -> 0 | DT15: =COUNTIFS('DETAIL SALES'!$Q$10:$Q$7501,'FILL RATE MANDATORY STOCK'!BK15,'DETAIL SALES'!$AB$10:$AB$7501,"No",'DETAIL SALES'!$C$10:$C$7501,"30") -> 0 | DU15: =COUNTIFS('DETAIL SALES'!$Q$10:$Q$7501,'FILL RATE MANDATORY STOCK'!\,'DETAIL SALES'!$AB$10:$AB$7501,"Full",'DETAIL SALES'!$C$10:$C$7501,"31") -> 0 | DV15: =COUNTIFS('DETAIL SALES'!$Q$10:$Q$7501,'FILL RATE MANDATORY STOCK'!BK15,'DETAIL SALES'!$AB$10:$AB$7501,"No",'DETAIL SALES'!$C$10:$C$7501,"31") -> 0 | DW15: =BM15+BO15+BQ15+BS15+BU15+BW15+BY15+CA15+CC15+CE15+CG15+CI15+CK15+CM15+CO15+CQ15+CS15+CU15+CW15+CY15+DA15+DC15+DE15+DG15+DI15+DK15+DM15+DO15+DQ15+DS15+DU15 -> 0 | DX15: =BN15+BP15+BR15+BT15+BV15+BX15+BZ15+CB15+CD15+CF15+CH15+CJ15+CL15+CN15+CP15+CR15+CT15+CV15+CX15+CZ15+DB15+DD15+DF15+DH15+DJ15+DL15+DN15+DP15+DR15+DT15+DV15 -> 0 | DY15: =DW15+DX15 -> 0 | DZ15: =DW15/DY15 -> #DIV/0!
